Workbook

Sheet nháp
B2: DỮ LIỆU HÀNG HÓA HÀNG KHÔNG
B3: Loại hình phục vụ | C3: Ngày | D3: BSX | E3: Điểm đóng hàng | F3: Điểm trả hàng | G3: TG xe đóng | H3: TG xe chạy | I3: TG xe đến | J3: TG hạ hàng | K3: Tình trạng hàng | L3: Ngày hạ hàng | M3: Khách hàng | N3: Kho đóng trả hàng | O3: Ghi chú | P3: Họ tên lái xe | Q3: km đi | R3: km đến | S3: PCS | T3: GW
B4: HHHK | C4: 46132 | D4: 20C04357 | E4: ASG | F4: ALSC | G4: 0.34722222 | H4: 0.375 | I4: 0.38194444 | J4: 0.39583333 | N4: ALSC | O4: EI | P4: Đặng Ngọc Lợi | Q4: 419064 | R4: 419067
B5: HHHK | C5: 46132 | D5: 20C04357 | E5: ALSC | F5: ASG | H5: 0.39583333 | I5: 0.39930556 | K5: K | P5: Đặng Ngọc lợi | Q5: 419067 | R5: 419070
B6: HHHK | C6: 46132 | D6: 20C04357 | E6: ASG | F6: ACSV | G6: 0.42013889 | H6: 0.46875 | I6: 0.47569444 | J6: 0.55555556 | N6: ACSV | O6: EI | P6: Đặng Ngọc Lợi | Q6: 419070 | R6: 419073
B7: HHHK | C7: 46132 | D7: 20C04357 | E7: ACSV | F7: ASG | H7: 0.55555556 | I7: 0.55902778 | K7: K | P7: Đặng Ngọc lợi | Q7: 419073 | R7: 419076
B8: HHHK | C8: 46132 | D8: 20C04357 | E8: ASG | F8: ACSV | G8: 0.5625 | H8: 0.57291667 | I8: 0.57986111 | J8: 0.61111111 | N8: ACSV | O8: EI | P8: Đặng Ngọc Lợi | Q8: 419076 | R8: 419079
B9: HHHK | C9: 46132 | D9: 20C04357 | E9: ACSV | F9: ASG | H9: 0.61484954 | I9: 0.61832176 | K9: K | P9: Đặng Ngọc lợi | Q9: 419079 | R9: 419082
B10: HHHK | C10: 46132 | D10: 20C04357 | E10: NBA | F10: ALSB | G10: 0.64583333 | H10: 0.69791667 | I10: 0.72569444 | J10: 0.75 | N10: ACSV | P10: Đặng Ngọc Lợi | Q10: 419082 | R10: 419117
B11: HHHK | C11: 46132 | D11: 20C04357 | E11: ALSB | F11: NBA | G11: 0.8125 | H11: 0.87847222 | I11: 0.90277778 | J11: 0.91319444 | N11: ALSC | P11: Đặng Ngọc Lợi | Q11: 419117 | R11: 419144
C14: DỮ LIỆU ĐIỂM ĐÓNG VÀ TRẢ: 1 ĐIỂM
C15: Ngày phát sinh | D15: BSX | E15: Điểm đóng hàng | F15: Điểm trả hàng | G15: Số Pallet | H15: Trọng tải tính cước | I15: Thời gian yêu cầu | J15: Thời gian đóng hàng | K15: Thời gian xe chạy | L15: Thời gian đến | M15: Thời gian hạ hàng | N15: Tên khách hàng | O15: Ghi chú | P15: Hình ảnh chứng từ | Q15: Họ tên lái xe | R15: km đi | S15: km đến | T15: Viết tắt điểm đóng hàng | U15: Viết tắt điển trả hàng | V15: Hành trình
B16: Hàng ngoài | C16: 46112 | D16: 99H01503 | E16: Công ty TNHH Fulian Technology ( Hồng Hải - Quang Châu), KCN Quang Châu, Phường Nếnh, Bắc Ninh | F16: ASGS, Yên Phong, Bắc Ninh | G16: 16 Palllet | H16: 10 | I16: 0.625 | J16: 0.65277778 | K16: 0.69097222 | L16: 0.72222222 | M16: 0.79166667 | N16: SAFO | Q16: Dương Văn Bộ | R16: 359298 | S16: 359354 | T16: Quang châu | U16: Yên Phong | V16: =+T16&" "&U16 -> Quang châu Yên Phong
B17: Hàng ngoài | C17: 46112 | D17: 29E12452 | E17: Công ty TNHH Fulian Technology ( Hồng Hải - Quang Châu), KCN Quang Châu, Phường Nếnh, Bắc Ninh | F17: ASGS, Yên Phong, Bắc Ninh | G17: 6 Palllet | H17: 5 | I17: 0.625 | J17: 0.625 | K17: 0.70138889 | L17: 0.72222222 | M17: 0.75 | N17: SAFO | Q17: Giáp Văn Định | R17: 133180 | S17: 133237 | T17: Quang châu | U17: Yên Phong | V17: =+T17&" "&U17 -> Quang châu Yên Phong
C19: DỮ LIỆU ĐIỂM ĐÓNG VÀ TRẢ: NHIỀU ĐIỂM
C20: Ngày phát sinh | D20: BSX | E20: Điểm đóng hàng | F20: Điểm trả hàng | I20: Thời gian yêu cầu | J20: Thời gian đóng hàng | K20: Thời gian xe chạy | L20: Thời gian đến | M20: Thời gian hạ hàng | N20: Tên khách hàng | O20: Ghi chú | P20: Hình ảnh chứng từ | Q20: Họ tên lái xe | R20: km đi | S20: km đến | T20: Viết tắt điểm đóng hàng | U20: Viết tắt điển trả hàng | V20: Hành trình
C21: 46116 | D21: 99H00902 | E21: KCN Vân Trung, Bắc Ninh | F21: ACSV/NCTS Nội Bài, Hà Nội | H21: 8 | I21: 0.5625 | J21: 0.5625 | K21: 0.63194444 | L21: 0.67361111 | M21: 0.73611111 | N21: SAFO | Q21: Ngô Văn Quỳ | R21: 432650 | S21: 432700 | T21: Vân Trung | U21: NBA | V21: =+T21&" "&U21 -> Vân Trung NBA
C22: 46116 | F22: ALSC Nội Bài, Hà Nội | H22: 8 | I22: 0.73611111 | J22: 0.73611111 | K22: 0.73611111 | L22: 0.74305556 | M22: 0.86111111 | N22: SAFO | Q22: Ngô Văn Quỳ | R22: 432700 | S22: 432705 | V22: =+T22&" "&U22
C23: 46116 | F23: ALSE KCN VSIP, Bắc Ninh | H23: 8 | I23: 0.86111111 | J23: 0.86111111 | K23: 0.86111111 | L23: 0.90972222 | M23: 0.95486111 | N23: SAFO | Q23: Ngô Văn Quỳ | R23: 432705 | S23: 432760 | V23: =+T23&" "&U23
C24: 46118 | D24: 99H01503 | E24: KCN Vân Trung, Bắc Ninh | F24: ACSV/NCTS Nội Bài, Hà Nội | H24: 8 | I24: 0.5625 | J24: 0.5625 | K24: 0.66319444 | L24: 0.71180556 | M24: 0.77083333 | N24: SAFO | Q24: Giáp Văn Định | R24: 133180 | S24: 133235 | T24: Vân Trung | U24: NBA | V24: =+T24&" "&U24 -> Vân Trung NBA
C25: 46118 | F25: ALSW Nội Bài, Hà Nội | H25: 8 | I25: 0.77083333 | J25: 0.77083333 | K25: 0.77083333 | L25: 0.78125 | M25: 0.85416667 | N25: SAFO | Q25: Giáp Văn Định | R25: 133235 | S25: 133237 | V25: =+T25&" "&U25
C26: 46118 | D26: 20C04937 | E26: KCN Quang Châu, Bắc Ninh | F26: ASG Nội Bài, Hà Nội | H26: 5 | I26: 0.76388889 | J26: 0.76388889 | K26: 0.76388889 | L26: 0.80555556 | M26: 0.83680556 | N26: SAFO | Q26: Hoàng Trường Anh | R26: 428092 | S26: 428133 | T26: Vân Trung | U26: NBA | V26: =+T26&" "&U26 -> Vân Trung NBA
C27: 46118 | F27: ALSE KCN VSIP, Bắc Ninh | H27: 5 | I27: 0.58333333 | J27: 0.58333333 | K27: 0.69791667 | L27: 0.74305556 | M27: 0.76388889 | N27: SAFO | Q27: Hoàng Trường Anh | R27: 428062 | S27: 428092
C31: DỮ LIỆU TỔNG HỢP TẤT CẢ CÁC LOẠI HÌNH Ở TRÊN
C32: Ngày | D32: BSX | E32: Hành trình | F32: TG xe đóng | G32: TG xe chạy | H32: TG xe đến | I32: TG hạ hàng | J32: Tình trạng hàng | K32: Ngày hạ hàng | L32: Khách hàng | M32: Kho đóng trả hàng | N32: Ghi chú | O32: Họ tên lái xe | P32: km đi | Q32: km đến | R32: PCS | S32: GW
C33: 46132 | D33: 20C04357 | E33: ASG ALSC | F33: 0.34722222 | G33: 0.375 | H33: 0.38194444 | I33: 0.39583333 | M33: ALSC | N33: EI | O33: Đặng Ngọc Lợi | P33: 419064 | Q33: 419067
C34: 46132 | D34: 20C04357 | E34: ALSC ASG | G34: 0.39583333 | H34: 0.39930556 | J34: K | O34: Đặng Ngọc lợi | P34: 419067 | Q34: 419070
C35: 46132 | D35: 20C04357 | E35: ASG ACSV | F35: 0.42013889 | G35: 0.46875 | H35: 0.47569444 | I35: 0.55555556 | M35: ACSV | N35: EI | O35: Đặng Ngọc Lợi | P35: 419070 | Q35: 419073
C36: 46132 | D36: 20C04357 | E36: ACSV ASG | G36: 0.55555556 | H36: 0.55902778 | J36: K | O36: Đặng Ngọc lợi | P36: 419073 | Q36: 419076
C37: 46132 | D37: 20C04357 | E37: ASG ACSV | F37: 0.5625 | G37: 0.57291667 | H37: 0.57986111 | I37: 0.61111111 | M37: ACSV | N37: EI | O37: Đặng Ngọc Lợi | P37: 419076 | Q37: 419079
C38: 46132 | D38: 20C04357 | E38: ACSV ASG | G38: 0.61484954 | H38: 0.61832176 | J38: K | O38: Đặng Ngọc lợi | P38: 419079 | Q38: 419082
C39: 46132 | D39: 20C04357 | E39: NBA ALSB | F39: 0.64583333 | G39: 0.69791667 | H39: 0.72569444 | I39: 0.75 | M39: ACSV | O39: Đặng Ngọc Lợi | P39: 419082 | Q39: 419117
C40: 46132 | D40: 20C04357 | E40: ALSB NBA | F40: 0.8125 | G40: 0.87847222 | H40: 0.90277778 | I40: 0.91319444 | M40: ALSC | O40: Đặng Ngọc Lợi | P40: 419117 | Q40: 419144
C41: 46112 | D41: 99H01503 | E41: Quang châu Yên Phong | F41: 0.65277778 | G41: 0.69097222 | H41: 0.72222222 | I41: 0.79166667 | L41: SAFO | O41: Dương Văn Bộ | P41: 359298 | Q41: 359354
C42: 46112 | D42: 29E12452 | E42: Quang châu Yên Phong | F42: 0.625 | G42: 0.70138889 | H42: 0.72222222 | I42: 0.75 | L42: SAFO | O42: Giáp Văn Định | P42: 133180 | Q42: 133237
C43: 46116 | D43: 99H00902 | E43: Vân Trung NBA | F43: 0.5625 | G43: 0.63194444 | H43: 0.67361111 | I43: 0.86111111 | L43: SAFO | O43: Ngô Văn Quỳ | P43: 432650 | Q43: 432760
C44: 46118 | D44: 99H01503 | E44: Vân Trung NBA | F44: 0.5625 | G44: 0.66319444 | H44: 0.71180556 | I44: 0.85416667 | L44: SAFO | O44: Giáp Văn Định | P44: 133180 | Q44: 133237
C45: 46118 | D45: 20C04937 | E45: Vân Trung NBA | F45: 0.58333333 | G45: 0.69791667 | H45: 0.74305556 | I45: 0.83680556 | L45: SAFO | O45: Hoàng Trường Anh | P45: 428062 | Q45: 428133
A50: Dữ liệu do điều hành nhập, nếu nhập sai lệch do k đúng tên địa điểm, phải hiểu chỉnh lại mất nhiều thời gian
A51: Dữ liệu trên hệ thống này chỉ là cơ sở dữ liệu, Còn 1 dữ liệu hoàn chỉnh đẩy đủ sẽ được tổ thanh toán up lên sau khi đã chốt dữ liệu
...

Sheet Bảng tổng hợp chuyến phục vụ
C1: Bảng tổng hợp chuyến vận chuyển (dữ liệu do điều hành và lái xe cập nhật theo thực tế) | Z1: BẢNG THỐNG KÊ TỔNG HỢP CÁC CHUYẾN ĐÃ PHỤC VỤ
C3: Dữ liệu HHHK (dòng này chỉ thể hiện để mô tả để em biết, còn trong form ko cần nhé) | Z3: Dữ liệu hàng ngoài đóng và trả 1 điểm
C4: Loại hình phục vụ | D4: Mã đơn hàng | E4: Ngày | F4: BSX | G4: Điểm đóng hàng | H4: Điểm trả hàng | I4: Thời gian đóng hàng | J4: Thời gian xe chạy | K4: Thời gian đến | L4: Thời gian hạ hàng | M4: Khách hàng | N4: Kho đóng trả hàng | O4: Ghi chú | P4: Họ tên lái xe | Q4: Km tại điểm nhận hàng | R4: Km tại điểm trả hàng | S4: PCS | T4: GW | U4: Loại hàng | V4: Trọng tải tính cước | W4: Hình ảnh | Y4: NOTE Từ dữ liệu chi tiết se chuyển sang bảng tổng hợp chuyến phụ vụ cần lưu ý | Z4: Loại hình phục vụ | AA4: Mã đơn hàng | AB4: Ngày | AC4: BSX | AD4: Hành trình | AE4: Thời gian đóng hàng | AF4: Thời gian xe chạy | AG4: Thời gian đến | AH4: Thời gian hạ hàng | AI4: Khách hàng | AJ4: Kho đóng trả hàng | AK4: Ghi chú | AL4: Họ tên lái xe | AM4: Km tại điểm nhận hàng | AN4: Km tại điểm trả hàng | AO4: PCS | AP4: GW | AQ4: Loại hàng | AR4: Trọng tải tính cước
C5: HHHK | D5: ASG1 | E5: 46132 | F5: 20C04357 | G5: ASG | H5: ALSC | I5: 46132.347 | J5: 46132.375 | K5: 46132.382 | L5: 46132.396 | N5: ALSC | O5: EI | P5: Đặng Ngọc Lợi | Q5: 419064 | R5: 419067 | S5: HHHK có mục này | T5: HHHK có mục này | V5: Auto theo DS xe | Y5: + Ghép điểm đóng hàng và điểm nhận hàng thành 1 hành trình | Z5: =+C5 -> HHHK | AA5: =+D5 -> ASG1 | AB5: =+E5 -> 46132 | AC5: =+F5 -> 20C04357 | AD5: =+G5&" "&H5 -> ASG ALSC | AE5: 46132.347 | AF5: 46132.375 | AG5: 46132.382 | AH5: 46132.396 | AJ5: =+N5 -> ALSC | AK5: =+O5 -> EI | AL5: =+P5 -> Đặng Ngọc Lợi | AM5: =+Q5 -> 419064 | AN5: =+R5 -> 419067
C6: HHHK | D6: ASG2 | E6: 46132 | F6: 20C04357 | G6: ASG | H6: ACSV | I6: 46132.42 | J6: 46132.469 | K6: 46132.476 | L6: 46132.556 | N6: ACSV | O6: EI | P6: Đặng Ngọc Lợi | Q6: 419070 | R6: 419073 | Z6: =+C6 -> HHHK | AA6: =+D6 -> ASG2 | AB6: =+E6 -> 46132 | AC6: =+F6 -> 20C04357 | AD6: =+G6&" "&H6 -> ASG ACSV | AE6: 46132.42 | AF6: 46132.469 | AG6: 46132.476 | AH6: 46132.556 | AJ6: =+N6 -> ACSV | AK6: =+O6 -> EI | AL6: =+P6 -> Đặng Ngọc Lợi | AM6: =+Q6 -> 419070 | AN6: =+R6 -> 419073
C7: HHHK | D7: ASG3 | E7: 46132 | F7: 20C04357 | G7: ASG | H7: ACSV | I7: 46132.562 | J7: 46132.573 | K7: 46132.58 | L7: 46132.611 | N7: ACSV | O7: EI | P7: Đặng Ngọc Lợi | Q7: 419076 | R7: 419079 | Z7: =+C7 -> HHHK | AA7: =+D7 -> ASG3 | AB7: =+E7 -> 46132 | AC7: =+F7 -> 20C04357 | AD7: =+G7&" "&H7 -> ASG ACSV | AE7: 46132.562 | AF7: 46132.573 | AG7: 46132.58 | AH7: 46132.611 | AJ7: =+N7 -> ACSV | AK7: =+O7 -> EI | AL7: =+P7 -> Đặng Ngọc Lợi | AM7: =+Q7 -> 419076 | AN7: =+R7 -> 419079
C8: HHHK | D8: ASG4 | E8: 46132 | F8: 20C04357 | G8: NBA | H8: ALSB | I8: 46132.646 | J8: 46132.698 | K8: 46132.726 | L8: 46134.75 | N8: ACSV | P8: Đặng Ngọc Lợi | Q8: 419082 | R8: 419117 | Z8: =+C8 -> HHHK | AA8: =+D8 -> ASG4 | AB8: =+E8 -> 46132 | AC8: =+F8 -> 20C04357 | AD8: =+G8&" "&H8 -> NBA ALSB | AE8: 46132.646 | AF8: 46132.698 | AG8: 46132.726 | AH8: 46134.75 | AJ8: =+N8 -> ACSV | AK8: =+O8 | AL8: =+P8 -> Đặng Ngọc Lợi | AM8: =+Q8 -> 419082 | AN8: =+R8 -> 419117
C9: HHHK | D9: ASG5 | E9: 46132 | F9: 20C04357 | G9: ALSB | H9: NBA | I9: 46132.812 | J9: 46132.878 | K9: 46132.903 | L9: 46133.913 | N9: ALSC | P9: Đặng Ngọc Lợi | Q9: 419117 | R9: 419144 | Z9: =+C9 -> HHHK | AA9: =+D9 -> ASG5 | AB9: =+E9 -> 46132 | AC9: =+F9 -> 20C04357 | AD9: =+G9&" "&H9 -> ALSB NBA | AE9: 46132.812 | AF9: 46132.878 | AG9: 46132.903 | AH9: 46133.913 | AJ9: =+N9 -> ALSC | AK9: =+O9 | AL9: =+P9 -> Đặng Ngọc Lợi | AM9: =+Q9 -> 419117 | AN9: =+R9 -> 419144
C12: Dữ liệu hàng ngoài đóng và trả 1 điểm (dòng này chỉ thể hiện để mô tả để em biết, còn trong form ko cần nhé)
C13: Hàng ngoài | D13: ASG6 | E13: 46112 | F13: 99H01503 | G13: Công ty TNHH Fulian Technology ( Hồng Hải - Quang Châu), KCN Quang Châu, Phường Nếnh, Bắc Ninh | H13: ASGS, Yên Phong, Bắc Ninh | I13: 46132.625 | J13: 46132.653 | K13: 46132.691 | L13: 46132.722 | M13: SAFO | P13: Dương Văn Bộ | Q13: 359298 | R13: 359354 | S13: 10 | T13: Hàng ngoài ko có mục này | U13: GRC | V13: 10 | Y13: + Chuyển các địa điểm đóng hàng và nhận hàng thành các địa điểm viết tắt và ghép lại thành 1 hành trình | Z13: =+C13 -> Hàng ngoài | AA13: =+D13 -> ASG6 | AB13: =+E13 -> 46112 | AC13: =+F13 -> 99H01503 | AD13: Quang Châu Yên Phong | AE13: =+I13 -> 46132.625 | AF13: =+J13 -> 46132.653 | AG13: =+K13 -> 46132.691 | AH13: =+L13 -> 46132.722 | AI13: =+M13 -> SAFO | AL13: =+P13 -> Dương Văn Bộ | AM13: =+Q13 -> 359298 | AN13: =+R13 -> 359354
C14: Hàng ngoài | D14: ASG7 | E14: 46112 | F14: 29E12452 | G14: Công ty TNHH Fulian Technology ( Hồng Hải - Quang Châu), KCN Quang Châu, Phường Nếnh, Bắc Ninh | H14: ASGS, Yên Phong, Bắc Ninh | I14: 46132.625 | J14: 46132.625 | K14: 46132.701 | L14: 46132.722 | M14: SAFO | P14: Giáp Văn Định | Q14: 133180 | R14: 133237 | S14: 5 | U14: DG | V14: 8 | Z14: =+C14 -> Hàng ngoài | AA14: =+D14 -> ASG7 | AB14: =+E14 -> 46112 | AC14: =+F14 -> 29E12452 | AD14: Quang Châu Yên Phong | AE14: =+I14 -> 46132.625 | AF14: =+J14 -> 46132.625 | AG14: =+K14 -> 46132.701 | AH14: =+L14 -> 46132.722 | AI14: =+M14 -> SAFO | AL14: =+P14 -> Giáp Văn Định | AM14: =+Q14 -> 133180 | AN14: =+R14 -> 133237
C17: Dữ liệu hàng ngoài đóng hoặc trả nhiều điểm (dòng này chỉ thể hiện để mô tả để em biết, còn trong form ko cần nhé)
C18: Hàng ngoài | D18: ASG8 | E18: 46116 | F18: 99H00902 | G18: KCN Vân Trung, Bắc Ninh | H18: ACSV/NCTS Nội Bài, Hà Nội | I18: 46132.562 | J18: 46132.562 | K18: 46132.632 | L18: 46132.674 | M18: SAFO | P18: Giáp Văn Định | Q18: 133180 | R18: 133237 | U18: 5 | V18: 8 | Y18: + Chuyển các địa điểm đóng hàng và nhận hàng thành địa điểm viết tắt sau đó ghép điểm đóng hàng đầu tiên và điểm trả hàng cuối cùng thành 1 hành trình + Thời gian đóng hàng lấy thời gian bắt đầu đóng hàng, thời gian xe chạy và thời gian xe đến ở chặng đầu tiên, thời gian hạ hàng được lấy ở chặng cuối cùng + Ngày hạ hàng là ngày hạ hàng ở điểm trả hàng cuối cùng | Z18: =+C18 -> Hàng ngoài | AA18: =+D18 -> ASG8 | AB18: =+E18 -> 46116 | AC18: =+F18 -> 99H00902 | AD18: Vân Trung ALSE | AE18: =+I18 -> 46132.562 | AF18: =+J18 -> 46132.562 | AG18: =+K18 -> 46132.632 | AH18: =+L20 -> 46133.076 | AI18: =+M18 -> SAFO | AL18: =+P18 -> Giáp Văn Định | AM18: =+Q18 -> 133180 | AN18: =+R18 -> 133237
C19: Hàng ngoài | D19: ASG8 | E19: 46116 | H19: ALSC Nội Bài, Hà Nội | I19: 46132.736 | J19: 46132.736 | K19: 46132.736 | L19: 46132.743 | M19: SAFO | P19: Giáp Văn Định | Q19: 133237 | R19: 133240 | U19: 5 | V19: 8 | Z19: =+C19 -> Hàng ngoài | AA19: =+D21 -> ASG9 | AB19: =+E21 -> 46118 | AC19: =+F21 -> 99H01503 | AD19: Vân Trung NBA | AE19: =+I21 -> 46132.562 | AF19: =+J21 -> 46132.562 | AG19: =+K21 -> 46132.663 | AH19: =+L22 -> 46132.781 | AI19: =+M21 -> SAFO | AL19: =+P21 -> Đặng Ngọc Lợi | AM19: =+Q21 -> 359298 | AN19: =+R21 -> 359354
C20: Hàng ngoài | D20: ASG8 | E20: 46116 | H20: ALSE KCN VSIP, Bắc Ninh | I20: 46132.861 | J20: 46132.861 | K20: 46132.861 | L20: 46133.076 | M20: SAFO | P20: Giáp Văn Định | Q20: 133240 | R20: 133280 | U20: 5 | V20: 8 | Z20: =+C20 -> Hàng ngoài | AA20: =+D23 -> ASG10 | AB20: =+E23 -> 46118 | AC20: =+F23 -> 20C04937 | AD20: Vân Trung NBA | AE20: =I23 -> 46132.583 | AF20: =J23 -> 46132.583 | AG20: =K23 -> 46132.698 | AH20: =L24 -> 46132.806 | AI20: =+M23 -> SAFO | AL20: =+P23 -> Giáp Văn Định | AM20: =+Q23 -> 359298 | AN20: =+R23 -> 359354
C21: Hàng ngoài | D21: ASG9 | E21: 46118 | F21: 99H01503 | G21: KCN Vân Trung, Bắc Ninh | H21: ACSV/NCTS Nội Bài, Hà Nội | I21: 46132.562 | J21: 46132.562 | K21: 46132.663 | L21: 46132.712 | M21: SAFO | P21: Đặng Ngọc Lợi | Q21: 359298 | R21: 359354 | U21: 3 | V21: 5
C22: Hàng ngoài | D22: ASG9 | E22: 46118 | H22: ALSW Nội Bài, Hà Nội | I22: 46132.771 | J22: 46132.771 | K22: 46132.771 | L22: 46132.781 | M22: SAFO | P22: Đặng Ngọc Lợi | Q22: 359354 | R22: 359357 | U22: 3 | V22: 5
C23: Hàng ngoài | D23: ASG10 | E23: 46118 | F23: 20C04937 | G23: KCN Quang Châu, Bắc Ninh | H23: ALSE KCN VSIP, Bắc Ninh | I23: 46132.583 | J23: 46132.583 | K23: 46132.698 | L23: 46132.743 | M23: SAFO | P23: Giáp Văn Định | Q23: 359298 | R23: 359354 | U23: 5 | V23: 8
C24: Hàng ngoài | D24: ASG10 | E24: 46118 | H24: ASG Nội Bài, Hà Nội | I24: 46132.764 | J24: 46132.764 | K24: 46132.764 | L24: 46132.806 | M24: SAFO | P24: Giáp Văn Định | Q24: 359354 | R24: 359399 | U24: 5 | V24: 8

Sheet Bảng dữ liệu hàng ngoài
B1: DỮ LIỆU ĐIỂM ĐÓNG VÀ TRẢ: 1 ĐIỂM
B2: Ngày phát sinh | C2: BSX | D2: Điểm đóng hàng | E2: Điểm trả hàng | F2: Số Pallet | G2: Loại hàng | H2: Trọng tải tính cước | I2: Thời gian yêu cầu | J2: Thời gian đóng hàng | K2: Thời gian xe chạy | L2: Thời gian đến | M2: Thời gian hạ hàng | N2: Tên khách hàng | O2: Ghi chú | P2: Hình ảnh chứng từ | Q2: Họ tên lái xe | R2: Km tại điểm nhận hàng | S2: Km tại điểm trả hàng
B3: 46112 | C3: 99H01503 | D3: Công ty TNHH Fulian Technology ( Hồng Hải - Quang Châu), KCN Quang Châu, Phường Nếnh, Bắc Ninh | E3: ASGS, Yên Phong, Bắc Ninh | F3: 15 Pallet | G3: GRC | H3: 10 | I3: 0.625 | J3: 0.65277778 | K3: 0.69097222 | L3: 0.72222222 | M3: 0.79166667 | N3: SAFO | Q3: Dương Văn Bộ | R3: 359298 | S3: 359354
B4: 46112 | C4: 29E12452 | D4: Công ty TNHH Fulian Technology ( Hồng Hải - Quang Châu), KCN Quang Châu, Phường Nếnh, Bắc Ninh | E4: ASGS, Yên Phong, Bắc Ninh | F4: 6 Carton | G4: DG | H4: 5 | I4: 0.625 | J4: 0.625 | K4: 0.70138889 | L4: 0.72222222 | M4: 0.75 | N4: SAFO | Q4: Giáp Văn Định | R4: 133180 | S4: 133237
B6: DỮ LIỆU ĐIỂM ĐÓNG VÀ TRẢ: NHIỀU ĐIỂM
B7: Ngày phát sinh | C7: BSX | D7: Điểm đóng hàng | E7: Điểm trả hàng | F7: Số Pallet | G7: Loại hàng | H7: Trọng tải tính cước | I7: Thời gian yêu cầu | J7: Thời gian đóng hàng | K7: Thời gian xe chạy | L7: Thời gian đến | M7: Thời gian hạ hàng | N7: Tên khách hàng | O7: Ghi chú | P7: Hình ảnh chứng từ | Q7: Họ tên lái xe | R7: Km tại điểm nhận hàng | S7: Km tại điểm trả hàng
B8: 46116 | C8: 99H00902 | D8: KCN Vân Trung, Bắc Ninh | E8: ACSV/NCTS Nội Bài, Hà Nội | F8: 5 Pallet | G8: GRC | H8: 8 | I8: 0.5625 | J8: 0.5625 | K8: 0.63194444 | L8: 0.67361111 | M8: 0.73611111 | N8: SAFO | Q8: Ngô Văn Quỳ | R8: 432650 | S8: 432700
B9: 46116 | E9: ALSC Nội Bài, Hà Nội | F9: 10 Carton | G9: GRC | H9: 8 | I9: 0.73611111 | J9: 0.73611111 | K9: 0.73611111 | L9: 0.74305556 | M9: 0.86111111 | N9: SAFO | Q9: Ngô Văn Quỳ | R9: 432700 | S9: 432705
B10: 46116 | E10: ALSE KCN VSIP, Bắc Ninh | F10: 8 | G10: GRC | H10: 8 | I10: 0.86111111 | J10: 0.86111111 | K10: 0.86111111 | L10: 0.90972222 | M10: 0.95486111 | N10: SAFO | Q10: Ngô Văn Quỳ | R10: 432705 | S10: 432760
B11: 46118 | C11: 99H01503 | D11: KCN Vân Trung, Bắc Ninh | E11: ACSV/NCTS Nội Bài, Hà Nội | F11: 15 | G11: GRC | H11: 8 | I11: 0.5625 | J11: 0.5625 | K11: 0.66319444 | L11: 0.71180556 | M11: 0.77083333 | N11: SAFO | Q11: Giáp Văn Định | R11: 133180 | S11: 133235
B12: 46118 | E12: ALSW Nội Bài, Hà Nội | F12: 2 | G12: GRC | H12: 8 | I12: 0.77083333 | J12: 0.77083333 | K12: 0.77083333 | L12: 0.78125 | M12: 0.85416667 | N12: SAFO | Q12: Giáp Văn Định | R12: 133235 | S12: 133237
B13: 46118 | C13: 20C04937 | D13: KCN Quang Châu, Bắc Ninh | E13: ASG Nội Bài, Hà Nội | F13: 3 | G13: GRC | H13: 5 | I13: 0.76388889 | J13: 0.76388889 | K13: 0.76388889 | L13: 0.80555556 | M13: 0.83680556 | N13: SAFO | Q13: Hoàng Trường Anh | R13: 428092 | S13: 428133
B14: 46118 | E14: ALSE KCN VSIP, Bắc Ninh | F14: 5 | G14: DG | H14: 5 | I14: 0.58333333 | J14: 0.58333333 | K14: 0.69791667 | L14: 0.74305556 | M14: 0.76388889 | N14: SAFO | Q14: Hoàng Trường Anh | R14: 428062 | S14: 428092

Sheet DATA location HHHK
A1: STT | B1: Khu vực | C1: Địa điểm viết tắt | D1: Tên công ty chi tiết | E1: Địa chỉ
A2: 1 | B2: NBA | C2: ACSV | D2: CÔNG TY CỔ PHẦN DỊCH VỤ HÀNG HÓA HÀNG KHÔNG VIỆT NAM | E2: Cảng hàng không Quốc tế Nội Bài, Nội Bài, Hà Nội | F2: =+VLOOKUP(C2,'Data locationHàng ngoài'!C:C,1,0) -> ACSV
A3: 2 | B3: NBA | C3: NCTS | D3: CÔNG TY CỔ PHẦN DỊCH VỤ HÀNG HÓA NỘI BÀI (NCTS) | E3: Cảng hàng không Quốc tế Nội Bài, Nội Bài, Hà Nội | F3: =+VLOOKUP(C3,'Data locationHàng ngoài'!C:C,1,0) -> NCTS
A4: 3 | B4: NBA | C4: ALSC | D4: CÔNG TY CỔ PHẦN NHÀ GA HÀNG HÓA ALS | E4: Cảng hàng không Quốc tế Nội Bài, Nội Bài, Hà Nội | F4: =+VLOOKUP(C4,'Data locationHàng ngoài'!C:C,1,0) -> ALSC
A5: 5 | B5: NBA | C5: DHL | D5: CÔNG TY CỔ PHẦN GIAO NHẬN TOÀN CẦU DHL (VIỆT NAM) | E5: Cảng hàng không Quốc tế Nội Bài, Nội Bài, Hà Nội | F5: =+VLOOKUP(C5,'Data locationHàng ngoài'!C:C,1,0) -> DHL
A6: 6 | B6: NBA | C6: ALSW | D6: CÔNG TY TNHH DỊCH VỤ KHO VẬN ALS (ALSW) | E6: Cảng hàng không Quốc tế Nội Bài, Nội Bài, Hà Nội | F6: =+VLOOKUP(C6,'Data locationHàng ngoài'!C:C,1,0) -> ALSW
A7: 7 | B7: NBA | C7: ASG | D7: CÔNG TY CỔ PHẦN TẬP ĐOÀN ASG | E7: Cảng hàng không Quốc tế Nội Bài, Nội Bài, Hà Nội | F7: =+VLOOKUP(C7,'Data locationHàng ngoài'!C:C,1,0) -> ASG
A8: 9 | B8: BN | C8: SEV | D8: CÔNG TY TNHH SAMSUNG ELECTRONICS VIỆT NAM (SEV) | E8: KCN Yên Phong, Yên Trung, Bắc Ninh | F8: =+VLOOKUP(C8,'Data locationHàng ngoài'!C:C,1,0) -> SEV
A9: 9 | B9: BN | C9: ALSB | D9: CÔNG TY TRÁCH NHIỆM HỮU HẠN ALS BẮC NINH | E9: KCN Yên Phong, Yên Trung, Bắc Ninh | F9: =+VLOOKUP(C9,'Data locationHàng ngoài'!C:C,1,0) -> ALSB
A10: 10 | B10: BN | C10: SDV | D10: CÔNG TY TNHH SAMSUNG DISPLAY VIỆT NAM (SDV) | E10: KCN Yên Phong, Yên Trung, Bắc Ninh | F10: =+VLOOKUP(C10,'Data locationHàng ngoài'!C:C,1,0) -> SDV
A11: 11 | B11: BN | C11: ASGS | D11: CÔNG TY CỔ PHẦN DỊCH VỤ SÂN BAY SÀI GÒN (ASGS) | E11: KCN Yên Phong, Yên Trung, Bắc Ninh | F11: =+VLOOKUP(C11,'Data locationHàng ngoài'!C:C,1,0) -> ASGS
A12: 12 | B12: BN | C12: CLC | D12: CÔNG TY CỔ PHẦN TIẾP VẬN THẾ KỶ (CLC) | E12: KCN Yên Phong, Yên Trung, Bắc Ninh | F12: =+VLOOKUP(C12,'Data locationHàng ngoài'!C:C,1,0) -> CLC
A13: 14 | B13: BN | C13: ALSE | D13: CÔNG TY CỔ PHẦN ALS ĐÔNG HÀ NỘI (ALSE) | E13: khu công nghiệp VSIP Bắc Ninh , Phù Chẩn, Từ Sơn, Bắc Ninh | F13: =+VLOOKUP(C13,'Data locationHàng ngoài'!C:C,1,0) -> ALSE
... A30: 34 | B30: NBO | C30: JUWKANG | D30: CÔNG TY TNHH JUKWANG PRECISION VIỆT NAM | E30: KCN Điềm Thụy, Điềm Thụy, Thái Nguyên | F30: =+VLOOKUP(C30,'Data locationHàng ngoài'!C:C,1,0) -> JUWKANG

Sheet Data locationHàng ngoài
A1: STT | B1: Khu vực | C1: Mã viết tắt nhà máy | D1: Địa điểm viết tắt | E1: Công ty | F1: Địa chỉ | G1: Xã/phường | H1: Tỉnh
A2: 1 | B2: BN | C2: SEV | D2: SEV | E2: CÔNG TY TNHH SAMSUNG ELECTRONICS VIỆT NAM (SEV) | F2: KCN Yên Phong, Yên Trung, Bắc Ninh | G2: Yên Trung | H2: Bắc Ninh
A3: 2 | B3: BN | C3: ALSB | D3: ALSB | E3: CÔNG TY TRÁCH NHIỆM HỮU HẠN ALS BẮC NINH | F3: KCN Yên Phong, Yên Trung, Bắc Ninh | G3: Yên Trung | H3: Bắc Ninh
A4: 3 | B4: BN | C4: SDV | D4: SDV | E4: CÔNG TY TNHH SAMSUNG DISPLAY VIỆT NAM (SDV) | F4: KCN Yên Phong, Yên Trung, Bắc Ninh | G4: Yên Trung | H4: Bắc Ninh
A5: 4 | B5: BN | C5: ASGS | D5: ASGS | E5: CÔNG TY CỔ PHẦN DỊCH VỤ SÂN BAY SÀI GÒN (ASGS) | F5: KCN Yên Phong, Yên Trung, Bắc Ninh | G5: Yên Trung | H5: Bắc Ninh
A6: 5 | B6: BN | C6: CLC | D6: CLC | E6: CÔNG TY CỔ PHẦN TIẾP VẬN THẾ KỶ (CLC) | F6: KCN Yên Phong, Yên Trung, Bắc Ninh | G6: Yên Trung | H6: Bắc Ninh
A7: 6 | B7: BN | C7: ALSE | D7: ALSE | E7: CÔNG TY CỔ PHẦN ALS ĐÔNG HÀ NỘI (ALSE) | F7: khu công nghiệp VSIP Bắc Ninh , Phù Chẩn, Từ Sơn, Bắc Ninh | G7: Từ Sơn | H7: Bắc Ninh
A8: 7 | B8: BN | C8: VDS | D8: QUẾ VÕ | E8: CÔNG TY TNHH VDS VIỆT NAM | F8: KCN Quế Võ 1, Phường Vân Dương, Bắc Ninh | G8: Vân Dương | H8: Bắc Ninh
A9: 8 | B9: BN | C9: FUYU | D9: QUANG CHÂU | E9: CÔNG TY TNHH TPCX FUYU | F9: KCN Quang Châu, Phường Nếnh, Tỉnh Bắc Ninh | G9: Nếnh | H9: Bắc Ninh
A10: 9 | B10: BN | C10: DOEW | D10: TỪ SƠN | E10: CÔNG TY DOEW | F10: Phường Từ Sơn, Tỉnh Bắc Ninh | G10: Từ Sơn | H10: Bắc Ninh
A11: 10 | B11: BN | C11: AMKOR | D11: YÊN PHONG | E11: CÔNG TY TNHH AMKOR TECHNOLOGY VIỆT NAM | F11: KCN Yên Phong II-C, Xã Yên Phong, Tỉnh Bắc Ninh | G11: Yên Trung | H11: Bắc Ninh
A12: 11 | B12: BN | C12: FUSHAN | D12: TỪ SƠN | E12: CÔNG TY TNHH FUSHAN TECHNOLOGY VN | F12: Số 8, đường 6, KCN VSIP Bắc Ninh, Phường Từ Sơn, Tỉnh Bắc Ninh | G12: Từ Sơn | H12: Bắc Ninh
A13: 12 | B13: BN | C13: RADIAN | D13: YÊN PHONG | E13: CÔNG TY TNHH RADIAN VIỆT NAM | F13: Nhà máy FA3 Cụm Fuji Precision, KCN Yên Phong, Xã Yên Phong, Tỉnh Bắc Ninh | G13: Yên Trung | H13: Bắc Ninh
... A217: 216 | B217: NBO | C217: ALSB | D217: ALSB | E217: CÔNG TY TRÁCH NHIỆM HỮU HẠN ALS BẮC NINH | F217: KCN Yên Phong, Yên Trung, Bắc Ninh | G217: Yên Trung | H217: Bắc Ninh

Sheet Khách hàng
A1: STT | B1: MÃ KHÁCH HÀNG | C1: TÊN ĐẦY ĐỦ
A2: 1 | B2: ADVANT | C2: CÔNG TY CỔ PHẦN LOGISTICS ADVANT
A3: 2 | B3: ALSB | C3: CÔNG TY TRÁCH NHIỆM HỮU HẠN ALS BẮC NINH
A4: 3 | B4: ALSE | C4: CÔNG TY CỔ PHẦN ALS ĐÔNG HÀ NỘI
A5: 4 | B5: ASGL | C5: CÔNG TY CỔ PHẦN LOGISTICS ASG
A6: 5 | B6: ASGS | C6: CÔNG TY CỔ PHẦN DỊCH VỤ SÂN BAY SÀI GÒN
A7: 6 | B7: ASGS (VFC) | C7: CÔNG TY CỔ PHẦN DỊCH VỤ SÂN BAY SÀI GÒN
A8: 7 | B8: ASGS (SAFO) | C8: CÔNG TY CỔ PHẦN DỊCH VỤ SÂN BAY SÀI GÒN
A9: 8 | B9: CLC | C9: CÔNG TY CỔ PHẦN TIẾP VẬN THẾ KỶ
A10: 9 | B10: KIOWAY | C10: CÔNG TY CỔ PHẦN KIOWAY
A11: 10 | B11: NHẬT MINH | C11: CÔNG TY TNHH THƯƠNG MẠI VÀ XÂY DỰNG NHẬT MINH HÀ NỘI
A12: 11 | B12: SDS HCM | C12: CHI NHÁNH CÔNG TY TNHH SAMSUNG SDS VIỆT NAM TẠI THÀNH PHỐ HỒ CHÍ MINH
A13: 12 | B13: SDS HN | C13: CÔNG TY TNHH SAMSUNG SDS VIỆT NAM
... A17: 16 | B17: Khách lẻ | C17: Nhập tên thực tế
